Workbook

Sheet 0.안내
B1: KING STUDIO 가격 모델링
B2: Pricing & Unit Economics Model — 파라미터 입력형 (방식 B)
B4: ■ 이 모델의 목적
B5: PRD 미해결 이슈 O3 해소용. 패키지 가격이 단위원가 대비 이익이 남는지, 할인을 다 얹어도
B6: 플러스인지, 월 몇 건을 팔아야 사업이 유지되는지를 계산한다.
B8: ■ 사용법
B9: 1. 노란 배경 + 파란 글씨 칸만 채우면 된다. 나머지는 자동 계산된다.
B10: 2. 입력은 전부 [1.입력값] 시트에 모여 있다. 거기 한 곳만 바꾸면 모든 시트가 갱신된다.
B11: 3. 모르는 값은 비워두거나 추정치를 넣고, 색으로 "확정/추정"을 구분해 관리하라.
B13: ■ 색상 규칙 (재무모델 표준)
B14: 파란 글씨 + 노란 배경 = 당신이 입력하는 값
B15: 검은 글씨 = 자동 계산 (수식)
... B38: 채워지기 전까지의 마진·손익분기 숫자는 의미가 없다.

Sheet 1.입력값
B1: 1. 입력값 (INPUTS)
B2: 노란 칸을 채우세요. 파란 글씨 = 입력, 검은 글씨 = 자동계산.
B4: 항목 | C4: 값 | D4: 단위 | E4: 비고 / 출처
B5: 1-A. 패키지 정가 (1인 기준, PRD 5.2 확정)
B6: Gold 정가 | C6: 400000 | D6: KRW | E6: PRD 5.2 확정
B7: Diamond 정가 | C7: 500000 | D7: KRW | E7: PRD 5.2 확정
B8: Premium 정가 | C8: 1500000 | D8: KRW | E8: PRD 5.2 확정
B9: 1Hour 정가 (대여) | C9: 100000 | D9: KRW | E9: PRD 5.2 확정, 한국어 전용
B10: 1Pro 정가 (대여) | C10: 300000 | D10: KRW | E10: PRD 5.2 확정, 한국어 전용
B11: K-Pop Making Class (1인) | C11: 150000 | D11: KRW | E11: PRD 5.2 확정, 단체
B12: 꿈길 (1인) | C12: 30000 | D12: KRW | E12: PRD 5.2 확정, 단체
B13: 워크샵 (1인) | C13: 50000 | D13: KRW | E13: PRD 5.2 확정, 단체
B14: 1-B. 세션당 변동비 (★ 입력 필요 — 한 건 팔릴 때마다 나가는 돈)
B15: 녹음 엔지니어 / 세션 (2h) | C15: 50000 | D15: KRW | E15: 입력: Gold·Diamond 2시간 세션
B16: 녹음 엔지니어 / Premium (3h) | C16: 50000 | D16: KRW | E16: 입력: Premium 3시간 세션
B17: 보컬 디렉팅 / 세션 | C17: 40000 | D17: KRW | E17: 입력: 디렉터 인건비 (엔지니어와 별개)
B18: 통역 / 세션 | C18: 40000 | D18: KRW | E18: 입력: 외국인 세션 통역비 (PRD 5.2 통역 포함)
B19: 촬영 담당 / 세션 | C19: 0 | D19: KRW | E19: 입력: 0 (현재 별도 비용 없음)
B20: 사진 셀렉트·후처리 / 세션 | C20: 0 | D20: KRW | E20: 입력: 0
B21: 믹싱·마스터링 / 1곡 | C21: 50000 | D21: KRW | E21: 입력: Diamond·Premium
B22: Premium MV 외주 / 1건 | C22: 500000 | D22: KRW | E22: 입력: 외부팀 납품 단가
B23: 곡 라이선스료 / 1곡 | C23: 0 | D23: KRW | E23: 입력: 현재 0
B24: 소모품·기타 / 세션 | C24: 10000 | D24: KRW | E24: 입력: USB·인화 등
B25: 1-C. 결제 수수료 (PRD 5.5 확정)
B26: KG이니시스 수수료율 | C26: 0.03 | D26: % | E26: PRD 확정
B27: PayPal 수수료율 | C27: 0.044 | D27: % | E27: PRD 확정
B28: PayPal 고정 수수료 | C28: 560 | D28: KRW | E28: PRD 확정, 건당
B29: 1-D. 할인 · 채널 수수료
B30: 친구초대 할인율 | C30: 0.1 | D30: % | E30: PRD 확정 (Diamond·Premium·단체만)
B31: 친구초대 할인 상한 | C31: 50000 | D31: KRW | E31: PRD 확정
B32: 프로모션 코드 기본 할인율 | C32: 0.1 | D32: % | E32: PRD 확정 (1~50% 범위)
B33: KLOOK 수수료율 | C33: 0.2 | D33: % | E33: 입력: 실제 정산 수수료율
B34: KKday 수수료율 | C34: 0.2 | D34: % | E34: 입력: 실제 정산 수수료율
B35: 1-E. 월 고정비 (★ 입력 필요 — 세션 수와 무관하게 나가는 돈)
B36: 스튜디오 임대료 / 월 | C36: 2530000 | D36: KRW | E36: 입력: STUDIO A
B37: 상주 인력 인건비 / 월 | C37: 0 | D37: KRW | E37: 입력: 0 (세션당 정산)
B38: 장비 감가상각·유지보수 / 월 | C38: 170000 | D38: KRW | E38: 입력: 월 환산
B39: 플랫폼 운영비 / 월 | C39: 452000 | D39: KRW | E39: 손익분기 포함 (실제 운영비)
B40: 기타 고정비 / 월 | C40: 300000 | D40: KRW | E40: 입력: 보험·통신·세무 등
B41: 월 고정비 합계 | C41: =SUM(C36:C40) | D41: KRW | E41: 자동 합계
...

Sheet 2.단위마진
B1: 2. 패키지별 단위 마진 (정가 · 자체 채널 기준)
B2: 한 건 팔 때 남는 돈. 자체 사이트 결제(OTA·할인 없음) 기준. 초록 글씨 = 입력값 시트 참조.
B4: 항목 | C4: Gold | D4: Diamond | E4: Premium | F4: 비고
B5: 매출 (정가, 1인) | C5: ='1.입력값'!$C$6 | D5: ='1.입력값'!$C$7 | E5: ='1.입력값'!$C$8 | F5: 정가
B6: 녹음 엔지니어 인건비 | C6: =-'1.입력값'!$C$15 | D6: =-'1.입력값'!$C$15 | E6: =-'1.입력값'!$C$16 | F6: Gold·Dia 2h / Prem 3h
B7: 보컬 디렉팅 인건비 | C7: =-'1.입력값'!$C$17 | D7: =-'1.입력값'!$C$17 | E7: =-'1.입력값'!$C$17 | F7: 전 패키지
B8: 통역 인건비 | C8: =-'1.입력값'!$C$18 | D8: =-'1.입력값'!$C$18 | E8: =-'1.입력값'!$C$18 | F8: 외국인 세션
B9: 촬영 인건비 | C9: =-'1.입력값'!$C$19 | D9: =-'1.입력값'!$C$19 | E9: =-'1.입력값'!$C$19 | F9: 전 패키지 사진 포함
B10: 사진 셀렉트·후처리 | C10: =-'1.입력값'!$C$20 | D10: =-'1.입력값'!$C$20 | E10: =-'1.입력값'!$C$20
B11: 믹싱·마스터링 | C11: =0 | D11: =-'1.입력값'!$C$21-'1.입력값'!$C$42 | E11: =-'1.입력값'!$C$21-'1.입력값'!$C$42 | F11: Gold 기본/Dia·Prem 믹싱+수정
B12: MV 외주 제작 | C12: =0 | D12: =0 | E12: =-'1.입력값'!$C$22 | F12: Premium만
B13: 곡 라이선스료 | C13: =-'1.입력값'!$C$23 | D13: =-'1.입력값'!$C$23 | E13: =-'1.입력값'!$C$23 | F13: 곡당
B14: 소모품·기타 | C14: =-'1.입력값'!$C$24 | D14: =-'1.입력값'!$C$24 | E14: =-'1.입력값'!$C$24
B15: 변동비 합계 (결제수수료 제외) | C15: =SUM(C6:C14) | D15: =SUM(D6:D14) | E15: =SUM(E6:E14)
B16: 결제 수수료 (PayPal 기준) | C16: =-('1.입력값'!$C$6*'1.입력값'!$C$27+'1.입력값'!$C$28) | D16: =-('1.입력값'!$C$7*'1.입력값'!$C$27+'1.입력값'!$C$28) | E16: =-('1.입력값'!$C$8*'1.입력값'!$C$27+'1.입력값'!$C$28) | F16: PayPal 4.4%+560 (외국인 보수적 가정)
B17: 단위 마진 (정가) | C17: =C5+C15+C16 | D17: =D5+D15+D16 | E17: =E5+E15+E16
B18: 마진율 | C18: =IF(C5=0,0,C17/C5) | D18: =IF(D5=0,0,D17/D5) | E18: =IF(E5=0,0,E17/E5)
B19: 【 2인 예약 】 매출 ×1.5, 인건비·통역 1팀 공통, 소모품 2배
B20: 2인 매출 (정가 ×1.5) | C20: ='1.입력값'!$C$6*1.5 | D20: ='1.입력값'!$C$7*1.5 | E20: ='1.입력값'!$C$8*1.5
B21: 2인 변동비 (소모품만 추가) | C21: =C15-'1.입력값'!$C$24 | D21: =D15-'1.입력값'!$C$24 | E21: =E15-'1.입력값'!$C$24
B22: 2인 결제수수료 (PayPal) | C22: =-('1.입력값'!$C$6*1.5*'1.입력값'!$C$27+'1.입력값'!$C$28) | D22: =-('1.입력값'!$C$7*1.5*'1.입력값'!$C$27+'1.입력값'!$C$28) | E22: =-('1.입력값'!$C$8*1.5*'1.입력값'!$C$27+'1.입력값'!$C$28)
B23: 2인 마진 (총액) | C23: =C20+C21+C22 | D23: =D20+D21+D22 | E23: =E20+E21+E22
B24: 2인 → 1인당 마진 | C24: =C23/2 | D24: =D23/2 | E24: =E23/2
B25: 2인 마진율 | C25: =IF(C20=0,0,C23/C20) | D25: =IF(D20=0,0,D23/D20) | E25: =IF(E20=0,0,E23/E20)
B27: ※ 1인 마진은 상단, 2인 마진은 위 블록. 2인은 매출 1.5배·인건비 고정이라 마진율이 더 높다.
B28: ※ 3~5인 마진 별도 산출 안함. 최저마진은 1인, 전 패키지 +. Gold PRD 5.2 최대 2인.
F31: 1인당 마진 | G31: (변동비 계산용)
F32: =D32/1 | G32: =($D$15-$D$14)+$D$14*1
F33: =D33/2 | G33: =($D$15-$D$14)+$D$14*2
F34: =D34/3 | G34: =($D$15-$D$14)+$D$14*3
F35: =D35/4 | G35: =($D$15-$D$14)+$D$14*4
F36: =D36/5 | G36: =($D$15-$D$14)+$D$14*5

Sheet 3.할인시나리오
B1: 3. 할인 시나리오별 마진
B2: 정가 마진에서 채널 수수료·할인을 뺐을 때 남는 마진. 최악 조합에서도 플러스인지 확인.
B4: 시나리오 | C4: Gold | D4: Diamond | E4: Premium
B5: ① 자체채널 정가 | C5: ='2.단위마진'!$C$17 | D5: ='2.단위마진'!$D$17 | E5: ='2.단위마진'!$E$17 | F5: 할인·OTA 없음 (시트2와 동일)
B6: ② 친구초대 10% (상한 5만) | C6: ='2.단위마진'!$C$17 | D6: ='2.단위마진'!$D$17-MIN('1.입력값'!$C$7*'1.입력값'!$C$30,'1.입력값'!$C$31) | E6: ='2.단위마진'!$E$17-MIN('1.입력값'!$C$8*'1.입력값'!$C$30,'1.입력값'!$C$31) | F6: Gold 미적용(PRD). Dia·Prem만 할인
B7: ③ 프로모션 10% | C7: ='2.단위마진'!$C$17-'1.입력값'!$C$6*'1.입력값'!$C$32 | D7: ='2.단위마진'!$D$17-'1.입력값'!$C$7*'1.입력값'!$C$32 | E7: ='2.단위마진'!$E$17-'1.입력값'!$C$8*'1.입력값'!$C$32 | F7: 전 패키지 적용 가능
B8: ④ KLOOK 채널 판매 | C8: ='2.단위마진'!$C$17-'1.입력값'!$C$6*'1.입력값'!$C$33 | D8: ='2.단위마진'!$D$17-'1.입력값'!$C$7*'1.입력값'!$C$33 | E8: ='2.단위마진'!$E$17-'1.입력값'!$C$8*'1.입력값'!$C$33 | F8: OTA 수수료만큼 마진 차감
B9: ⑤ KKday 채널 판매 | C9: ='2.단위마진'!$C$17-'1.입력값'!$C$6*'1.입력값'!$C$34 | D9: ='2.단위마진'!$D$17-'1.입력값'!$C$7*'1.입력값'!$C$34 | E9: ='2.단위마진'!$E$17-'1.입력값'!$C$8*'1.입력값'!$C$34 | F9: OTA 수수료만큼 마진 차감
B10: ⑥ 최악: KLOOK + 프로모션 | C10: ='2.단위마진'!$C$17-'1.입력값'!$C$6*'1.입력값'!$C$33-'1.입력값'!$C$6*'1.입력값'!$C$32 | D10: ='2.단위마진'!$D$17-'1.입력값'!$C$7*'1.입력값'!$C$33-'1.입력값'!$C$7*'1.입력값'!$C$32 | E10: ='2.단위마진'!$E$17-'1.입력값'!$C$8*'1.입력값'!$C$33-'1.입력값'!$C$8*'1.입력값'!$C$32 | F10: 채널 수수료 + 할인 동시
B12: ※ 음수(괄호 표시)가 나오는 칸 = 그 조합으로 팔면 손해. 특히 ⑥ 최악 시나리오를 주시.
B13: ※ Gold·1Hour·1Pro는 친구초대 제외(PRD). 대여·단체는 별도 모델 필요 시 확장.

Sheet 4.손익분기
B1: 4. 손익분기점 (Break-even)
B2: 월 고정비를 덮으려면 월 몇 건을 팔아야 하는가. 패키지 믹스 가정에 따라 달라진다.
B4: 월 고정비 합계 | C4: ='1.입력값'!$C$41 | E4: 입력값 시트 1-E 합계
B6: [가정 A] Diamond만 판매할 경우
B7: 항목 | C7: 값
B8: Diamond 단위 마진 (정가) | C8: ='2.단위마진'!$D$17
B9: 손익분기 월 판매 건수 | C9: =IF(C8<=0,"마진≤0",ROUNDUP(C4/C8,0)) | E9: 이 건수 이상 팔아야 흑자
B11: [가정 B] 패키지 믹스 (월 판매 건수를 직접 입력)
B12: 패키지 | C12: 월 판매 건수(입력) | D12: 월 기여 마진
B13: Gold | C13: 0 | D13: =C13*'2.단위마진'!$C$17
B14: Diamond | C14: 0 | D14: =C14*'2.단위마진'!$D$17
B15: Premium | C15: 0 | D15: =C15*'2.단위마진'!$E$17
B16: 월 기여 마진 합계 | D16: =SUM(D13:D15)
B17: 월 손익 (기여마진 − 고정비) | D17: =D16-C4
B18: 판정 | D18: =IF(D17>0,"흑자",IF(D17=0,"손익분기","적자"))
B20: ※ 가정 B의 노란 칸에 월 예상 판매 건수를 넣으면 월 손익이 자동 계산된다.
B21: ※ 모든 마진은 정가 기준. 할인·OTA 비중이 크면 시트3 값으로 별도 시나리오를 짜야 한다.

Sheet 5.단체마진
B1: 5. 단체 패키지 마진 (인원당 정액 × 인원)
B2: 매출=인원×정액. 인건비는 회당 고정이라 인원 많을수록 마진율↑. 최소/최대 인원 시나리오.
B4: ■ 꿈길 (1인당 정액, 국내·통역 제외)
B5: 항목 | C5: 최소 10명 | D5: 최대 15명
B6: 매출 (인원 × 정액) | C6: ='1.입력값'!$C$12*10 | D6: ='1.입력값'!$C$12*15
B7: 인건비 (회당 고정) | C7: =-('1.입력값'!$C$44+'1.입력값'!$C$45) | D7: =-('1.입력값'!$C$44+'1.입력값'!$C$45)
B8: 소모품 (인원당) | C8: =-'1.입력값'!$C$47*10 | D8: =-'1.입력값'!$C$47*15
B9: 결제수수료 | C9: =-'1.입력값'!$C$12*10*'1.입력값'!$C$48 | D9: =-'1.입력값'!$C$12*15*'1.입력값'!$C$48
B10: 세션 마진 (총액) | C10: =C6+C7+C8+C9 | D10: =D6+D7+D8+D9
B11: 마진율 | C11: =IF(C6=0,0,C10/C6) | D11: =IF(D6=0,0,D10/D6)
B12: 1인당 마진 | C12: =C10/10 | D12: =D10/15
B14: ■ 워크샵 (1인당 정액, 국내·통역 제외)
B15: 항목 | C15: 최소 5명 | D15: 최대 15명
B16: 매출 (인원 × 정액) | C16: ='1.입력값'!$C$13*5 | D16: ='1.입력값'!$C$13*15
B17: 인건비 (회당 고정) | C17: =-('1.입력값'!$C$44+'1.입력값'!$C$45) | D17: =-('1.입력값'!$C$44+'1.입력값'!$C$45)
B18: 소모품 (인원당) | C18: =-'1.입력값'!$C$47*5 | D18: =-'1.입력값'!$C$47*15
B19: 결제수수료 | C19: =-'1.입력값'!$C$13*5*'1.입력값'!$C$48 | D19: =-'1.입력값'!$C$13*15*'1.입력값'!$C$48
B20: 세션 마진 (총액) | C20: =C16+C17+C18+C19 | D20: =D16+D17+D18+D19
B21: 마진율 | C21: =IF(C16=0,0,C20/C16) | D21: =IF(D16=0,0,D20/D16)
B22: 1인당 마진 | C22: =C20/5 | D22: =D20/15
B24: ■ K-Pop Making Class (1인당 정액, 다국어·통역 포함)
B25: 항목 | C25: 최소 3명 | D25: 최대 15명
B26: 매출 (인원 × 정액) | C26: ='1.입력값'!$C$11*3 | D26: ='1.입력값'!$C$11*15
B27: 인건비 (회당 고정) | C27: =-('1.입력값'!$C$44+'1.입력값'!$C$45+'1.입력값'!$C$46) | D27: =-('1.입력값'!$C$44+'1.입력값'!$C$45+'1.입력값'!$C$46)
B28: 소모품 (인원당) | C28: =-'1.입력값'!$C$47*3 | D28: =-'1.입력값'!$C$47*15
B29: 결제수수료 | C29: =-('1.입력값'!$C$11*3*'1.입력값'!$C$27+'1.입력값'!$C$28) | D29: =-('1.입력값'!$C$11*15*'1.입력값'!$C$27+'1.입력값'!$C$28)
B30: 세션 마진 (총액) | C30: =C26+C27+C28+C29 | D30: =D26+D27+D28+D29
B31: 마진율 | C31: =IF(C26=0,0,C30/C26) | D31: =IF(D26=0,0,D30/D26)
B32: 1인당 마진 | C32: =C30/3 | D32: =D30/15
B34: ※ 매출=인원×정액, 인건비는 회당 고정. 그래서 최대 인원일 때 마진율이 가장 높다.
B35: ※ 국내 단체(꿈길·워크샵)는 B2B 계좌이체(수수료≈0) 가정. Making Class는 PayPal 가정.
B36: ※ 노출: 국내 사이트=꿈길·워크샵 / 다국어 사이트=Making Class (PRD 5.4).
